Workbook

Sheet Overview
A1: GATE CSE 2027 – 12-Week Crash Plan (13 Oct → 31 Dec 2026)
A2: Goal: cover 6 of the 10 GATE sections by 31 Dec (Engineering Maths every day + 5 core subjects) while preparing for IPU end-terms. January = PYQs only.
A4: 1. Key dates
A5: Practical exams (5th sem) | B5: 26 Nov – 6 Dec 2026 (load reduced to 2.5 h/day)
A6: Theory exams (all 2–5 PM) | B6: 15 Dec DAA (CIC-311) · 17 Dec Compiler Design (CIC-303) · 19 Dec OS (CIC-305) · 22 Dec Computer Networks (CIC-307) · 24 Dec Software Engineering (CIC-309) · 28 Dec Economics (HS-301)
A7: GATE 2027 | B7: Early February 2027 (check the official IIT Madras date)
A9: 2. How a day works (Mon–Sat)
A10: 1. Easy start (15–20 min) | B10: Aptitude (15 of 100 GATE marks): 8–10 easy questions. Verbal topics → GATE Overflow verbal lessons; quant/reasoning → Saurabh Thakur's aptitude course (see Playlist Directory).
A11: 2. ONE maths lecture (30–40 min) | B11: Exactly one Engineering Maths lecture a day: Discrete (22 days) → Linear Algebra (7) → Probability & Statistics (12) → Calculus (9) → 2 PYQ days.
A12: 3. Main subject lecture (55–75 min) | B12: The day's topic from the subject sheet. Watch at 1.25x–1.5x and make short notes.
A13: 4. PYQ practice (20–45 min) | B13: PYQs on exactly that topic from GO-PDFs. Do not skip this.
A14: Ramp-up | B14: Week 1 (13–17 Oct) = 2 h/day, week 2 = 2.5 h/day, from 26 Oct = 3 h/day. Practical window = 2.5 h. Sundays = revision + timed test (subjects + maths).
A16: 3. What's covered by 31 Dec (60% of sections)
A17: Included (6 sections) | B17: Engineering Maths (Discrete, Linear Algebra, Probability, Calculus), Programming & Data Structures, Algorithms, Compiler Design, Operating System, Computer Networks. Four of these are your IPU subjects, so one session serves GATE and university.
A18: Not included (4 sections) | B18: Digital Logic, COA, Theory of Computation, Databases → January, using the PYQ video-solution playlists as your learning source.
A19: Order | B19: Subjects: C → DS → Algorithms → Compiler Design → OS → Networks, so each is learned before its university exam and revised Dec 11–22.
A21: 4. Sheets in this workbook
A22: Progress | B22: Auto % complete per subject, maths and aptitude + overall GATE coverage.
A23: Master Planner | B23: Every day 13 Oct – 31 Dec: subject, maths lecture, time split.
A24: 1–6 subject sheets | B24: Per day: main lecture (+ maths/aptitude shown for reference), playlist title · teacher (clickable), video search links, textbook, PYQs, and a Status for that subject only.
A25: 7 Engineering Maths | B25: The 52 daily maths lectures with playlist, teacher, search links and its own Status.
A26: 8 Aptitude | B26: Daily aptitude topics in 4 rounds (learn → practice → timed → full sets) with its own Status.
A27: Sunday Revision / Uni Exams & Wrap-up | B27: Weekly revision with the week's topics auto-listed; Dec 11–31 exam prep and GATE recap.
A28: Playlist Directory | B28: Every playlist with title, teacher/channel, uploader, video count and link.
A30: 5. Please read
A31: Video links | B31: YouTube does not let me read what is inside a playlist, so I could not verify an individual video URL for each topic and did not invent any. Instead every day has the verified playlist (title · teacher, clickable) plus a 'Search this lecture ▶' link that opens YouTube search for that exact topic with the teacher's name. If you paste a playlist's video titles into the chat, I can map each day to the exact video number.
A32: Teachers | B32: Names come from the playlist titles/owners. Where YouTube only shows a channel (e.g. GO Classes, NPTEL), that's what is written – no guessed names.
A33: Maths gaps | B33: Your PDF has no dedicated First-Order Logic, Relations, Functions or Posets/Lattices playlist. Days 4–5 and 7–11 use the closest listed playlists; the Notes column says what to search if a topic isn't there.
A34: Aptitude | B34: I verified GATE Overflow's verbal lessons (linked from GATE Overflow's own post) and Saurabh Thakur's aptitude course (Unacademy, not YouTube). I could not verify a YouTube quant playlist.
A35: Your subjects | B35: Confirmed: Software Engineering (CIC-309) is a subject this semester; DBMS is not, so it is left to January GATE study. Software Engineering and Economics syllabi were not shared, so Dec 23 & Dec 25–27 use typical topics – replace with your IPU units.
A36: Time check | B36: Adding a daily maths lecture trimmed the main lecture to 75 min (at 1.5x ≈ 110 min of video). If a day overruns, finish the main lecture and push the maths lecture to the next day's slot; Sundays absorb the slack.
A37: Status | B37: Each subject has its own Status: subject sheets 1–6 track only that subject, sheet 7 tracks Maths, sheet 8 tracks Aptitude. Done = green, In Progress = yellow. Progress updates automatically.
A38: Late start (13 Oct) | B38: Plan now starts on Tue 13 Oct instead of Mon 12 Oct. Every lecture moved one study-day later; Sundays, practicals and university exam dates did not move. The one lecture that no longer fits before 10 Dec is moved: CN Day 8 (Application layer) → 21 Dec, and Maths M52 + Aptitude Day 52 → 29 Dec.

Sheet Progress
A1: Progress Tracker (auto-updates from Status columns)
A3: Sheet | B3: Total study days | C3: Days marked Done | D3: % complete
A4: C Programming | B4: =COUNTA('1 C Programming'!A12:A16) -> 5 | C4: =COUNTIF('1 C Programming'!P12:P16,"Done") -> 0 | D4: =IF(B4=0,0,C4/B4) -> 0
A5: Data Structures | B5: =COUNTA('2 Data Structures'!A13:A21) -> 9 | C5: =COUNTIF('2 Data Structures'!P13:P21,"Done") -> 0 | D5: =IF(B5=0,0,C5/B5) -> 0
A6: Algorithms (DAA) | B6: =COUNTA('3 Algorithms DAA'!A13:A25) -> 13 | C6: =COUNTIF('3 Algorithms DAA'!P13:P25,"Done") -> 0 | D6: =IF(B6=0,0,C6/B6) -> 0
A7: Compiler Design | B7: =COUNTA('4 Compiler Design'!A14:A20) -> 7 | C7: =COUNTIF('4 Compiler Design'!P14:P20,"Done") -> 0 | D7: =IF(B7=0,0,C7/B7) -> 0
A8: Operating Systems | B8: =COUNTA('5 Operating Systems'!A13:A22) -> 10 | C8: =COUNTIF('5 Operating Systems'!P13:P22,"Done") -> 0 | D8: =IF(B8=0,0,C8/B8) -> 0
A9: Computer Networks | B9: =COUNTA('6 Computer Networks'!A13:A20) -> 8 | C9: =COUNTIF('6 Computer Networks'!P13:P20,"Done") -> 0 | D9: =IF(B9=0,0,C9/B9) -> 0
A10: Engineering Maths | B10: =COUNTA('7 Engineering Maths'!A5:A56) -> 52 | C10: =COUNTIF('7 Engineering Maths'!K5:K56,"Done") -> 0 | D10: =IF(B10=0,0,C10/B10) -> 0
A11: Aptitude | B11: =COUNTA('8 Aptitude'!A11:A62) -> 52 | C11: =COUNTIF('8 Aptitude'!J11:J62,"Done") -> 0 | D11: =IF(B11=0,0,C11/B11) -> 0
A12: Sunday revisions | B12: =COUNTA('Sunday Revision'!A5:A12) -> 8 | C12: =COUNTIF('Sunday Revision'!H5:H12,"Done") -> 0 | D12: =IF(B12=0,0,C12/B12) -> 0
A13: Uni exam prep & wrap-up days | B13: =COUNTA('Uni Exams & Wrap-up'!A5:A25) -> 21 | C13: =COUNTIF('Uni Exams & Wrap-up'!I5:I25,"Done") -> 0 | D13: =IF(B13=0,0,C13/B13) -> 0
A15: GATE 2027 syllabus coverage (10 sections, each weighted equally)
A16: GATE section | B16: Weight (assumed) | C16: Covered in this plan? | D16: Progress | E16: Contribution
A17: Engineering Mathematics | B17: 0.1 | C17: Yes | D17: =D10 -> 0 | E17: =B17*D17 -> 0
A18: Digital Logic | B18: 0.1 | C18: No – January (PYQs) | D18: 0 | E18: =B18*D18 -> 0
A19: Computer Organization & Architecture | B19: 0.1 | C19: No – January (PYQs) | D19: 0 | E19: =B19*D19 -> 0
A20: Programming & Data Structures | B20: 0.1 | C20: Yes | D20: =IF(B4+B5=0,0,(C4+C5)/(B4+B5)) -> 0 | E20: =B20*D20 -> 0
A21: Algorithms | B21: 0.1 | C21: Yes | D21: =D6 -> 0 | E21: =B21*D21 -> 0
A22: Theory of Computation | B22: 0.1 | C22: No – January (PYQs) | D22: 0 | E22: =B22*D22 -> 0
A23: Compiler Design | B23: 0.1 | C23: Yes | D23: =D7 -> 0 | E23: =B23*D23 -> 0
A24: Operating System | B24: 0.1 | C24: Yes | D24: =D8 -> 0 | E24: =B24*D24 -> 0
A25: Databases | B25: 0.1 | C25: No – January (PYQs) | D25: 0 | E25: =B25*D25 -> 0
A26: Computer Networks | B26: 0.1 | C26: Yes | D26: =D9 -> 0 | E26: =B26*D26 -> 0
A27: TOTAL GATE SYLLABUS COMPLETED | B27: =SUM(B17:B26) -> 1 | E27: =SUM(E17:E26) -> 0
A29: Weights are an assumption (equal share per section; blue = editable). With daily maths, 6 of 10 sections are covered, so the ceiling by 31 Dec is 60%.

Sheet Master Planner
A1: Master Planner – 13 Oct to 31 Dec 2026 (every day)
A2: Read-only calendar. Tick progress in the subject sheets / Maths sheet (Status column).
A4: Date | B4: Day | C4: Type | D4: Subject | E4: Main focus | F4: Maths lecture (1/day) | G4: Easy start (min) | H4: Maths (min) | I4: Main block (min) | J4: Practice / test (min) | K4: Total (hrs) | L4: Note
A5: 46308 | B5: =TEXT(A5,"ddd") -> Tue | C5: GATE learning | D5: C Programming | E5: Day 1: Basics: data types, operators, precedence | F5: M1: Propositional logic I: propositions, connectives, truth tables | G5: 15 | H5: 30 | I5: 55 | J5: 20 | K5: =(G5+H5+I5+J5)/60 -> 2
A6: 46309 | B6: =TEXT(A6,"ddd") -> Wed | C6: GATE learning | D6: C Programming | E6: Day 2: Control flow & I/O | F6: M2: Propositional logic II: equivalences, tautology, normal forms | G6: 15 | H6: 30 | I6: 55 | J6: 20 | K6: =(G6+H6+I6+J6)/60 -> 2
A7: 46310 | B7: =TEXT(A7,"ddd") -> Thu | C7: GATE learning | D7: C Programming | E7: Day 3: Functions, recursion & storage classes | F7: M3: Propositional logic III: inference, validity, functional completeness | G7: 15 | H7: 30 | I7: 55 | J7: 20 | K7: =(G7+H7+I7+J7)/60 -> 2
A8: 46311 | B8: =TEXT(A8,"ddd") -> Fri | C8: GATE learning | D8: C Programming | E8: Day 4: Arrays, strings & pointer basics | F8: M4: First-order logic I: predicates & quantifiers | G8: 15 | H8: 30 | I8: 55 | J8: 20 | K8: =(G8+H8+I8+J8)/60 -> 2
A9: 46312 | B9: =TEXT(A9,"ddd") -> Sat | C9: GATE learning | D9: C Programming | E9: Day 5: Advanced pointers, structs, unions, malloc, macros | F9: M5: First-order logic II: translation & nested quantifiers | G9: 15 | H9: 30 | I9: 55 | J9: 20 | K9: =(G9+H9+I9+J9)/60 -> 2
A10: 46313 | B10: =TEXT(A10,"ddd") -> Sun | C10: Weekly revision + test | D10: Revision | E10: Revise the week's topics (incl. maths), timed PYQ test, error log | F10: Maths revision inside the test | G10: 30 | H10: 0 | I10: 90 | J10: 60 | K10: =(G10+H10+I10+J10)/60 -> 3
A11: 46314 | B11: =TEXT(A11,"ddd") -> Mon | C11: GATE learning | D11: Data Structures | E11: Day 1: Arrays & singly linked list | F11: M6: Sets: operations, power set, cardinality | G11: 20 | H11: 35 | I11: 65 | J11: 30 | K11: =(G11+H11+I11+J11)/60 -> 2.5
A12: 46315 | B12: =TEXT(A12,"ddd") -> Tue | C12: GATE learning | D12: Data Structures | E12: Day 2: Doubly/circular linked list & stacks | F12: M7: Relations I: types & representation | G12: 20 | H12: 35 | I12: 65 | J12: 30 | K12: =(G12+H12+I12+J12)/60 -> 2.5
A13: 46316 | B13: =TEXT(A13,"ddd") -> Wed | C13: GATE learning | D13: Data Structures | E13: Day 3: Expression conversion, queues & deque | F13: M8: Relations II: equivalence relations, partitions, closures | G13: 20 | H13: 35 | I13: 65 | J13: 30 | K13: =(G13+H13+I13+J13)/60 -> 2.5
A14: 46317 | B14: =TEXT(A14,"ddd") -> Thu | C14: GATE learning | D14: Data Structures | E14: Day 4: Binary trees & traversals | F14: M9: Functions: injective, surjective, bijective | G14: 20 | H14: 35 | I14: 65 | J14: 30 | K14: =(G14+H14+I14+J14)/60 -> 2.5
A15: 46318 | B15: =TEXT(A15,"ddd") -> Fri | C15: GATE learning | D15: Data Structures | E15: Day 5: BST & AVL trees | F15: M10: Partial orders & Hasse diagrams | G15: 20 | H15: 35 | I15: 65 | J15: 30 | K15: =(G15+H15+I15+J15)/60 -> 2.5
A16: 46319 | B16: =TEXT(A16,"ddd") -> Sat | C16: GATE learning | D16: Data Structures | E16: Day 6: Binary heaps & priority queue | F16: M11: Lattices | G16: 20 | H16: 35 | I16: 65 | J16: 30 | K16: =(G16+H16+I16+J16)/60 -> 2.5
... A30: 46333 | B30: =TEXT(A30,"ddd") -> Sat | C30: GATE + Uni learning | D30: Algorithms (DAA) | E30: Day 9: Minimum spanning trees & union-find | F30: M23: Matrices: types & operations | G30: 20 | H30: 40 | I30: 75 | J30: 45 | K30: =(G30+H30+I30+J30)/60 -> 3
A31: 46334 | B31: =TEXT(A31,"ddd") -> Sun | C31: Weekly revision + test | D31: Revision | E31: Diwali (approx.) – light day: only error-log review | G31: 20 | H31: 0 | I31: 0 | J31: 40 | K31: =(G31+H31+I31+J31)/60 -> 1 | L31: Festival – keep it light
A32: 46335 | B32: =TEXT(A32,"ddd") -> Mon | C32: GATE + Uni learning | D32: Algorithms (DAA) | E32: Day 10: Shortest paths | F32: M24: Determinants | G32: 20 | H32: 40 | I32: 75 | J32: 45 | K32: =(G32+H32+I32+J32)/60 -> 3
A33: 46336 | B33: =TEXT(A33,"ddd") -> Tue | C33: GATE + Uni learning | D33: Algorithms (DAA) | E33: Day 11: Dynamic programming I | F33: M25: Rank & inverse | G33: 20 | H33: 40 | I33: 75 | J33: 45 | K33: =(G33+H33+I33+J33)/60 -> 3
A34: 46337 | B34: =TEXT(A34,"ddd") -> Wed | C34: GATE + Uni learning | D34: Algorithms (DAA) | E34: Day 12: Dynamic programming II | F34: M26: Systems of linear equations | G34: 20 | H34: 40 | I34: 75 | J34: 45 | K34: =(G34+H34+I34+J34)/60 -> 3
A35: 46338 | B35: =TEXT(A35,"ddd") -> Thu | C35: GATE + Uni learning | D35: Algorithms (DAA) | E35: Day 13: Uni-only: backtracking, branch & bound, NP-completeness | F35: M27: Eigenvalues & eigenvectors | G35: 20 | H35: 40 | I35: 75 | J35: 45 | K35: =(G35+H35+I35+J35)/60 -> 3
A36: 46339 | B36: =TEXT(A36,"ddd") -> Fri | C36: GATE + Uni learning | D36: Compiler Design | E36: Day 1: Compiler phases & lexical analysis | F36: M28: Eigen properties: Cayley-Hamilton & diagonalisation | G36: 20 | H36: 40 | I36: 75 | J36: 45 | K36: =(G36+H36+I36+J36)/60 -> 3
A37: 46340 | B37: =TEXT(A37,"ddd") -> Sat | C37: GATE + Uni learning | D37: Compiler Design | E37: Day 2: Parsing I: top-down & LL(1) | F37: M29: LU decomposition + LA problem-solving | G37: 20 | H37: 40 | I37: 75 | J37: 45 | K37: =(G37+H37+I37+J37)/60 -> 3
A38: 46341 | B38: =TEXT(A38,"ddd") -> Sun | C38: Weekly revision + test | D38: Revision | E38: Revise the week's topics (incl. maths), timed PYQ test, error log | F38: Maths revision inside the test | G38: 30 | H38: 0 | I38: 90 | J38: 60 | K38: =(G38+H38+I38+J38)/60 -> 3
A39: 46342 | B39: =TEXT(A39,"ddd") -> Mon | C39: GATE + Uni learning | D39: Compiler Design | E39: Day 3: Parsing II: bottom-up, LR(0) & SLR(1) | F39: M30: Probability basics | G39: 20 | H39: 40 | I39: 75 | J39: 45 | K39: =(G39+H39+I39+J39)/60 -> 3
A40: 46343 | B40: =TEXT(A40,"ddd") -> Tue | C40: GATE + Uni learning | D40: Compiler Design | E40: Day 4: Parsing III: CLR(1), LALR(1), operator precedence | F40: M31: Conditional probability & independence | G40: 20 | H40: 40 | I40: 75 | J40: 45 | K40: =(G40+H40+I40+J40)/60 -> 3
A41: 46344 | B41: =TEXT(A41,"ddd") -> Wed | C41: GATE + Uni learning | D41: Compiler Design | E41: Day 5: Syntax-directed translation | F41: M32: Bayes' theorem & total probability | G41: 20 | H41: 40 | I41: 75 | J41: 45 | K41: =(G41+H41+I41+J41)/60 -> 3
A42: 46345 | B42: =TEXT(A42,"ddd") -> Thu | C42: GATE + Uni learning | D42: Compiler Design | E42: Day 6: Intermediate code & runtime environments | F42: M33: Random variables: PMF, PDF, CDF | G42: 20 | H42: 40 | I42: 75 | J42: 45 | K42: =(G42+H42+I42+J42)/60 -> 3
A43: 46346 | B43: =TEXT(A43,"ddd") -> Fri | C43: GATE + Uni learning | D43: Compiler Design | E43: Day 7: Code optimisation & data-flow analysis | F43: M34: Expectation, variance & standard deviation | G43: 20 | H43: 40 | I43: 75 | J43: 45 | K43: =(G43+H43+I43+J43)/60 -> 3
... A48: 46351 | B48: =TEXT(A48,"ddd") -> Wed | C48: GATE + Uni learning | D48: Operating Systems | E48: Day 4: CPU scheduling II | F48: M38: Exponential distribution | G48: 20 | H48: 40 | I48: 75 | J48: 45 | K48: =(G48+H48+I48+J48)/60 -> 3
A49: 46352 | B49: =TEXT(A49,"ddd") -> Thu | C49: GATE + Uni learning | D49: Operating Systems | E49: Day 5: Process synchronisation I | F49: M39: Normal distribution | G49: 20 | H49: 35 | I49: 65 | J49: 30 | K49: =(G49+H49+I49+J49)/60 -> 2.5 | L49: Practical-exam window: lighter 2.5h load
A50: 46353 | B50: =TEXT(A50,"ddd") -> Fri | C50: GATE + Uni learning | D50: Operating Systems | E50: Day 6: Process synchronisation II | F50: M40: Statistics: mean, median, mode & standard deviation | G50: 20 | H50: 35 | I50: 65 | J50: 30 | K50: =(G50+H50+I50+J50)/60 -> 2.5 | L50: Practical-exam window: lighter 2.5h load
A51: 46354 | B51: =TEXT(A51,"ddd") -> Sat | C51: GATE + Uni learning | D51: Operating Systems | E51: Day 7: Deadlocks | F51: M41: Probability problem-solving: Bayes + distributions | G51: 20 | H51: 35 | I51: 65 | J51: 30 | K51: =(G51+H51+I51+J51)/60 -> 2.5 | L51: Practical-exam window: lighter 2.5h load
A52: 46355 | B52: =TEXT(A52,"ddd") -> Sun | C52: Weekly revision + test | D52: Revision | E52: Revise the week's topics (incl. maths), timed PYQ test, error log | F52: Maths revision inside the test | G52: 30 | H52: 0 | I52: 90 | J52: 60 | K52: =(G52+H52+I52+J52)/60 -> 3
A53: 46356 | B53: =TEXT(A53,"ddd") -> Mon | C53: GATE + Uni learning | D53: Operating Systems | E53: Day 8: Memory management: paging & segmentation | F53: M42: Calculus: limits | G53: 20 | H53: 35 | I53: 65 | J53: 30 | K53: =(G53+H53+I53+J53)/60 -> 2.5 | L53: Practical-exam window: lighter 2.5h load
A54: 46357 | B54: =TEXT(A54,"ddd") -> Tue | C54: GATE + Uni learning | D54: Operating Systems | E54: Day 9: Virtual memory | F54: M43: Calculus: continuity | G54: 20 | H54: 35 | I54: 65 | J54: 30 | K54: =(G54+H54+I54+J54)/60 -> 2.5 | L54: Practical-exam window: lighter 2.5h load
A55: 46358 | B55: =TEXT(A55,"ddd") -> Wed | C55: GATE + Uni learning | D55: Operating Systems | E55: Day 10: File systems, disk scheduling & I/O | F55: M44: Calculus: differentiability | G55: 20 | H55: 35 | I55: 65 | J55: 30 | K55: =(G55+H55+I55+J55)/60 -> 2.5 | L55: Practical-exam window: lighter 2.5h load
A56: 46359 | B56: =TEXT(A56,"ddd") -> Thu | C56: GATE + Uni learning | D56: Computer Networks | E56: Day 1: Layering, switching & performance metrics | F56: M45: Mean value theorems | G56: 20 | H56: 35 | I56: 65 | J56: 30 | K56: =(G56+H56+I56+J56)/60 -> 2.5 | L56: Practical-exam window: lighter 2.5h load
A57: 46360 | B57: =TEXT(A57,"ddd") -> Fri | C57: GATE + Uni learning | D57: Computer Networks | E57: Day 2: Data link I: framing & error detection | F57: M46: Maxima & minima | G57: 20 | H57: 35 | I57: 65 | J57: 30 | K57: =(G57+H57+I57+J57)/60 -> 2.5 | L57: Practical-exam window: lighter 2.5h load
A58: 46361 | B58: =TEXT(A58,"ddd") -> Sat | C58: GATE + Uni learning | D58: Computer Networks | E58: Day 3: Data link II: flow control & ARQ | F58: M47: Integration I | G58: 20 | H58: 35 | I58: 65 | J58: 30 | K58: =(G58+H58+I58+J58)/60 -> 2.5 | L58: Practical-exam window: lighter 2.5h load
...

Sheet 1 C Programming
A1: C Programming – day-by-day plan
A2: GATE (foundation) | The STATUS column here tracks only THIS subject. Maths is tracked in sheet 7, Aptitude in sheet 8.
A4: Playlists & teachers
A5: Main playlist | D5: C Programming | GATE 2024 | Vishvadeep Gothi Sir · Vishvadeep Gothi Sir [40 videos]
A6: Revision / PYQ playlist | D6: Introduction to Programming in C - Satyadev Nandakumar | IIT Kanpur: NPTEL · Satyadev Nandakumar (IIT Kanpur) [55 videos]
A7: Topic-wise PYQs | D7: GATE Overflow GO-PDFs (2025) → open 'Programming in C'
A8: Textbook | D8: K&R – The C Programming Language (2E), ch 1-8
A9: Free tests | D9: GO2017 Programming 1 | E9: GO Programming Test 2 | F9: Programming GATE2020 PG-1 | G9: Programming GATE2020 PG-2
A11: Day # | B11: Date | C11: Day | D11: Aptitude today (reference – track in sheet 8) | E11: MATHS lecture today (reference – track in sheet 7) | F11: Maths playlist · teacher (click) | G11: Maths video search ▶ | H11: MAIN lecture topic | I11: What's covered | J11: Main playlist · teacher (click) | K11: Main video search ▶ | L11: Also use today: PYQ / extra playlist · teacher (click) | M11: Textbook | N11: Practice (PYQs) | O11: Planned hrs (whole day) | P11: STATUS – this subject only | Q11: Notes
A12: 1 | B12: 46308 | C12: =TEXT(B12,"ddd") -> Tue | D12: Aptitude: Percentages & ratios – 8-10 easy Qs (15 min). Source: Complete Course on General Aptitude for GATE & ESE 2025 & 2026 (Unacademy) | E12: Day 1: Propositional logic I: propositions, connectives, truth tables | F12: Propositional Logic - Complete Summary, All GATE PYQs & Practice Questions | Discrete Mathematics · GO Classes for GATE CS (instructor not named in playlist) | G12: Search this lecture ▶ | H12: Basics: data types, operators, precedence | I12: C program structure, data types & sizes, variables, all operators (incl. bitwise, ++/-- tricks), precedence/associativity, implicit & explicit type conversion. | J12: C Programming | GATE 2024 | Vishvadeep Gothi Sir · Vishvadeep Gothi Sir | K12: Search this lecture ▶ | L12: Introduction to Programming in C - Satyadev Nandakumar | IIT Kanpur: NPTEL · Satyadev Nandakumar (IIT Kanpur) | M12: K&R ch 1-2 | N12: GO-PDFs → Programming in C → Operators & expressions / data types – 10 Qs (output tracing) | O12: 2 | P12: Not Started
A13: 2 | B13: 46309 | C13: =TEXT(B13,"ddd") -> Wed | D13: Aptitude: Time & work – 8-10 easy Qs (15 min). Source: Complete Course on General Aptitude for GATE & ESE 2025 & 2026 (Unacademy) | E13: Day 2: Propositional logic II: equivalences, tautology, normal forms | F13: Propositional Logic - Complete Summary, All GATE PYQs & Practice Questions | Discrete Mathematics · GO Classes for GATE CS (instructor not named in playlist) | G13: Search this lecture ▶ | H13: Control flow & I/O | I13: if/else, switch, loops, break/continue, printf/scanf format specifiers, tricky output questions. | J13: C Programming | GATE 2024 | Vishvadeep Gothi Sir · Vishvadeep Gothi Sir | K13: Search this lecture ▶ | L13: Introduction to Programming in C - Satyadev Nandakumar | IIT Kanpur: NPTEL · Satyadev Nandakumar (IIT Kanpur) | M13: K&R ch 3, 7.2-7.3 | N13: GO-PDFs → Programming in C → Loops & control flow output questions – 10 Qs | O13: 2 | P13: Not Started
A14: 3 | B14: 46310 | C14: =TEXT(B14,"ddd") -> Thu | D14: Aptitude: Speed, time & distance – 8-10 easy Qs (15 min). Source: Complete Course on General Aptitude for GATE & ESE 2025 & 2026 (Unacademy) | E14: Day 3: Propositional logic III: inference, validity, functional completeness | F14: Propositional Logic - Complete Summary, All GATE PYQs & Practice Questions | Discrete Mathematics · GO Classes for GATE CS (instructor not named in playlist) | G14: Search this lecture ▶ | H14: Functions, recursion & storage classes | I14: Function call/return, call by value, recursion (trace stack frames), scope, auto/static/extern/register. | J14: C Programming | GATE 2024 | Vishvadeep Gothi Sir · Vishvadeep Gothi Sir | K14: Search this lecture ▶ | L14: Introduction to Programming in C - Satyadev Nandakumar | IIT Kanpur: NPTEL · Satyadev Nandakumar (IIT Kanpur) | M14: K&R ch 4 | N14: GO-PDFs → Programming in C → Recursion & storage-class PYQs – 12 Qs | O14: 2 | P14: Not Started
A15: 4 | B15: 46311 | C15: =TEXT(B15,"ddd") -> Fri | D15: Aptitude: Profit/loss & averages – 8-10 easy Qs (15 min). Source: Complete Course on General Aptitude for GATE & ESE 2025 & 2026 (Unacademy) | E15: Day 4: First-order logic I: predicates & quantifiers | F15: Propositional Logic - Complete Summary, All GATE PYQs & Practice Questions | Discrete Mathematics · GO Classes for GATE CS (instructor not named in playlist) | G15: Search this lecture ▶ | H15: Arrays, strings & pointer basics | I15: 1-D/2-D arrays, row-major address calculation, strings & string.h functions, pointer declaration, pointer arithmetic. | J15: C Programming | GATE 2024 | Vishvadeep Gothi Sir · Vishvadeep Gothi Sir | K15: Search this lecture ▶ | L15: Introduction to Programming in C - Satyadev Nandakumar | IIT Kanpur: NPTEL · Satyadev Nandakumar (IIT Kanpur) | M15: K&R ch 5.1-5.5 | N15: GO-PDFs → Programming in C → Arrays & pointers PYQs – 12 Qs | O15: 2 | P15: Not Started | Q15: If FOL isn't inside this playlist, search 'GO Classes first order logic' (not in your resource PDF).
A16: 5 | B16: 46312 | C16: =TEXT(B16,"ddd") -> Sat | D16: Aptitude: Number series & sequences – 8-10 easy Qs (15 min). Source: Complete Course on General Aptitude for GATE & ESE 2025 & 2026 (Unacademy) | E16: Day 5: First-order logic II: translation & nested quantifiers | F16: Propositional Logic - Complete Summary, All GATE PYQs & Practice Questions | Discrete Mathematics · GO Classes for GATE CS (instructor not named in playlist) | G16: Search this lecture ▶ | H16: Advanced pointers, structs, unions, malloc, macros | I16: Pointer-to-pointer, array of pointers, function pointers, struct/union sizes & padding, malloc/calloc/free, #define macros pitfalls. | J16: C Programming | GATE 2024 | Vishvadeep Gothi Sir · Vishvadeep Gothi Sir | K16: Search this lecture ▶ | L16: Introduction to Programming in C - Satyadev Nandakumar | IIT Kanpur: NPTEL · Satyadev Nandakumar (IIT Kanpur) | M16: K&R ch 5.6-5.12, 6 | N16: GO-PDFs → Programming in C → Pointers/structs PYQs – 15 Qs + full C topic recap | O16: 2 | P16: Not Started | Q16: Same note as day 4.
N17: Total planned hours | O17: =SUM(O12:O16) -> 10

Sheet 2 Data Structures
A1: Data Structures – day-by-day plan
A2: GATE (foundation) | The STATUS column here tracks only THIS subject. Maths is tracked in sheet 7, Aptitude in sheet 8.
A4: Playlists & teachers
A5: Main playlist | D5: Data Structures By Vishwadeep · Vishwadeep Sir [40 videos]
A6: Revision / PYQ playlist | D6: Data Structure: GATE PYQs | GATE/ESE 2022 | Vishvadeep Sir · Vishvadeep Sir (Unacademy Computer Science) [23 videos]
A7: More | D7: Computer Sc - Data Structures and Algorithms (NPTEL) · Dr. Naveen Garg, IIT Delhi [36 videos]
A8: Topic-wise PYQs | D8: GATE Overflow GO-PDFs (2025) → open 'Data Structures'
A9: Textbook | D9: Karumanchi – Data Structures & Algorithms Made Easy (chapter names given per day)
A10: Free tests | D10: Data Structure Set 2 | E10: DS GATE2020 PG-1 | F10: DS GATE2020 PG-2 | G10: DS GATE2020 PG-3 | H10: DS GATE2020 PG-4
A12: Day # | B12: Date | C12: Day | D12: Aptitude today (reference – track in sheet 8) | E12: MATHS lecture today (reference – track in sheet 7) | F12: Maths playlist · teacher (click) | G12: Maths video search ▶ | H12: MAIN lecture topic | I12: What's covered | J12: Main playlist · teacher (click) | K12: Main video search ▶ | L12: Also use today: PYQ / extra playlist · teacher (click) | M12: Textbook | N12: Practice (PYQs) | O12: Planned hrs (whole day) | P12: STATUS – this subject only | Q12: Notes
A13: 1 | B13: 46314 | C13: =TEXT(B13,"ddd") -> Mon | D13: Aptitude: Basic counting & probability (aptitude level) – 8-10 easy Qs (20 min). Source: Complete Course on General Aptitude for GATE & ESE 2025 & 2026 (Unacademy) | E13: Day 6: Sets: operations, power set, cardinality | F13: Set Theory - GATE PYQs, Summary, Practice, Revision | Discrete Mathematics · GO Classes for GATE CS (instructor not named in playlist) | G13: Search this lecture ▶ | H13: Arrays & singly linked list | I13: Array operations & complexity, singly linked list: insert/delete/search/reverse, find middle, detect loop. | J13: Data Structures By Vishwadeep · Vishwadeep Sir | K13: Search this lecture ▶ | L13: Data Structure: GATE PYQs | GATE/ESE 2022 | Vishvadeep Sir · Vishvadeep Sir (Unacademy Computer Science) | M13: Karumanchi: Linked Lists | N13: GO-PDFs → Data Structures → Linked list PYQs – 10 Qs | O13: 2.5 | P13: Not Started
A14: 2 | B14: 46315 | C14: =TEXT(B14,"ddd") -> Tue | D14: Aptitude: Data interpretation (tables, bar charts) – 8-10 easy Qs (20 min). Source: Complete Course on General Aptitude for GATE & ESE 2025 & 2026 (Unacademy) | E14: Day 7: Relations I: types & representation | F14: Set Theory - GATE PYQs, Summary, Practice, Revision | Discrete Mathematics · GO Classes for GATE CS (instructor not named in playlist) | G14: Search this lecture ▶ | H14: Doubly/circular linked list & stacks | I14: Doubly & circular LL, stack (array & LL), push/pop, stack applications. | J14: Data Structures By Vishwadeep · Vishwadeep Sir | K14: Search this lecture ▶ | L14: Data Structure: GATE PYQs | GATE/ESE 2022 | Vishvadeep Sir · Vishvadeep Sir (Unacademy Computer Science) | M14: Karumanchi: Linked Lists, Stacks | N14: GO-PDFs → Data Structures → Stack & LL PYQs – 10 Qs | O14: 2.5 | P14: Not Started | Q14: Closest playlist from your PDF; if relations aren't covered, search 'GO Classes relations discrete mathematics'.
A15: 3 | B15: 46316 | C15: =TEXT(B15,"ddd") -> Wed | D15: Aptitude: Verbal: tenses & subject-verb agreement – 8-10 easy Qs (20 min). Source: GATE Overflow – verbal aptitude lessons | E15: Day 8: Relations II: equivalence relations, partitions, closures | F15: Set Theory - GATE PYQs, Summary, Practice, Revision | Discrete Mathematics · GO Classes for GATE CS (instructor not named in playlist) | G15: Search this lecture ▶ | H15: Expression conversion, queues & deque | I15: Infix/postfix/prefix conversion & evaluation, queue, circular queue, deque, stack using queues & queue using stacks. | J15: Data Structures By Vishwadeep · Vishwadeep Sir | K15: Search this lecture ▶ | L15: Data Structure: GATE PYQs | GATE/ESE 2022 | Vishvadeep Sir · Vishvadeep Sir (Unacademy Computer Science) | M15: Karumanchi: Stacks, Queues | N15: GO-PDFs → Data Structures → Stack/Queue PYQs – 12 Qs | O15: 2.5 | P15: Not Started | Q15: Same note as day 7.
A16: 4 | B16: 46317 | C16: =TEXT(B16,"ddd") -> Thu | D16: Aptitude: Verbal: sentence completion & prepositions – 8-10 easy Qs (20 min). Source: GATE Overflow – verbal aptitude lessons | E16: Day 9: Functions: injective, surjective, bijective | F16: Set Theory - GATE PYQs, Summary, Practice, Revision | Discrete Mathematics · GO Classes for GATE CS (instructor not named in playlist) | G16: Search this lecture ▶ | H16: Binary trees & traversals | I16: Tree terminology, binary tree properties (nodes/height), in/pre/post/level-order, construct tree from two traversals, number of trees (Catalan). | J16: Data Structures By Vishwadeep · Vishwadeep Sir | K16: Search this lecture ▶ | L16: Data Structure: GATE PYQs | GATE/ESE 2022 | Vishvadeep Sir · Vishvadeep Sir (Unacademy Computer Science) | M16: Karumanchi: Trees | N16: GO-PDFs → Data Structures → Binary tree PYQs – 12 Qs | O16: 2.5 | P16: Not Started | Q16: Same note as day 7.
A17: 5 | B17: 46318 | C17: =TEXT(B17,"ddd") -> Fri | D17: Aptitude: Verbal: synonyms, antonyms & idioms – 8-10 easy Qs (20 min). Source: GATE Overflow – verbal aptitude lessons | E17: Day 10: Partial orders & Hasse diagrams | F17: Set Theory - GATE PYQs, Summary, Practice, Revision | Discrete Mathematics · GO Classes for GATE CS (instructor not named in playlist) | G17: Search this lecture ▶ | H17: BST & AVL trees | I17: BST insert/delete/search, inorder = sorted, height-balanced AVL trees & rotations, min/max nodes in AVL. | J17: Data Structures By Vishwadeep · Vishwadeep Sir | K17: Search this lecture ▶ | L17: Data Structure: GATE PYQs | GATE/ESE 2022 | Vishvadeep Sir · Vishvadeep Sir (Unacademy Computer Science) | M17: Karumanchi: Trees (BST, AVL) | N17: GO-PDFs → Data Structures → BST/AVL PYQs – 12 Qs | O17: 2.5 | P17: Not Started | Q17: Same note as day 7.
A18: 6 | B18: 46319 | C18: =TEXT(B18,"ddd") -> Sat | D18: Aptitude: Reading comprehension (1 passage) – 8-10 easy Qs (20 min). Source: GATE Overflow – verbal aptitude lessons | E18: Day 11: Lattices | F18: Set Theory - GATE PYQs, Summary, Practice, Revision | Discrete Mathematics · GO Classes for GATE CS (instructor not named in playlist) | G18: Search this lecture ▶ | H18: Binary heaps & priority queue | I18: Heap property, insert/delete-min, heapify, build-heap O(n), heap sort idea, priority queue. | J18: Data Structures By Vishwadeep · Vishwadeep Sir | K18: Search this lecture ▶ | L18: Data Structure: GATE PYQs | GATE/ESE 2022 | Vishvadeep Sir · Vishvadeep Sir (Unacademy Computer Science) | M18: Karumanchi: Priority Queues & Heaps | N18: GO-PDFs → Data Structures → Heap PYQs – 10 Qs | O18: 2.5 | P18: Not Started | Q18: Same note as day 7.
A19: 7 | B19: 46321 | C19: =TEXT(B19,"ddd") -> Mon | D19: Aptitude: Para-jumbles & sentence ordering – 8-10 easy Qs (20 min). Source: GATE Overflow – verbal aptitude lessons | E19: Day 12: Monoids, semigroups & groups | F19: Group Theory Complete Course - Abstract Algebra Course | Discrete Mathematics | Monoid, Groupoid, Semigroup, Abelian Group, Cyclic Group, Subgroup · GO Classes for GATE CS (instructor not named in playlist) | G19: Search this lecture ▶ | H19: Graph representation & basic traversals | I19: Directed/undirected graphs, adjacency matrix vs list, degree, paths/cycles, BFS/DFS first look (full treatment in Algorithms). | J19: Data Structures By Vishwadeep · Vishwadeep Sir | K19: Search this lecture ▶ | L19: Data Structure: GATE PYQs | GATE/ESE 2022 | Vishvadeep Sir · Vishvadeep Sir (Unacademy Computer Science) | M19: Karumanchi: Graph Algorithms (intro) | N19: GO-PDFs → Data Structures → Graph basics PYQs – 10 Qs | O19: 3 | P19: Not Started
A20: 8 | B20: 46322 | C20: =TEXT(B20,"ddd") -> Tue | D20: Aptitude: Logical reasoning: arrangements & puzzles – 8-10 easy Qs (20 min). Source: Complete Course on General Aptitude for GATE & ESE 2025 & 2026 (Unacademy) | E20: Day 13: Subgroups, cyclic groups & Lagrange's theorem | F20: Group Theory Complete Course - Abstract Algebra Course | Discrete Mathematics | Monoid, Groupoid, Semigroup, Abelian Group, Cyclic Group, Subgroup · GO Classes for GATE CS (instructor not named in playlist) | G20: Search this lecture ▶ | H20: DS output-tracing & complexity PYQs | I20: Mixed code-tracing on LL/stack/queue/tree; time complexity of operations (table of all structures). | J20: Data Structures By Vishwadeep · Vishwadeep Sir | K20: Search this lecture ▶ | L20: Data Structure: GATE PYQs | GATE/ESE 2022 | Vishvadeep Sir · Vishvadeep Sir (Unacademy Computer Science) | M20: — | N20: GO-PDFs → Data Structures → Mixed DS PYQs – 20 Qs; build a complexity cheat-table | O20: 3 | P20: Not Started
A21: 9 | B21: 46323 | C21: =TEXT(B21,"ddd") -> Wed | D21: Aptitude: Spatial reasoning: paper folding, cubes, patterns – 8-10 easy Qs (20 min). Source: Complete Course on General Aptitude for GATE & ESE 2025 & 2026 (Unacademy) | E21: Day 14: Graph basics: degrees, handshake, special graphs | F21: Graph Theory Complete Course - Discrete Mathematics | Complete Graph Theory Course | GO Classes · GO Classes for GATE CS (instructor not named in playlist) | G21: Search this lecture ▶ | H21: DS full-topic test | I21: Timed mini-test over entire DS, then fix errors with video solutions. | J21: Data Structures By Vishwadeep · Vishwadeep Sir | K21: Search this lecture ▶ | L21: Data Structure: GATE PYQs | GATE/ESE 2022 | Vishvadeep Sir · Vishvadeep Sir (Unacademy Computer Science) | M21: — | N21: GO-PDFs → Data Structures → Attempt 'Data Structure Set 2' or a GATE2020 DS test (timed 45 min) | O21: 3 | P21: Not Started
N22: Total planned hours | O22: =SUM(O13:O21) -> 24

Sheet 3 Algorithms DAA
A1: Algorithms (DAA) – day-by-day plan
A2: GATE + Uni (CIC-311 DAA, 15 Dec) | The STATUS column here tracks only THIS subject. Maths is tracked in sheet 7, Aptitude in sheet 8.
A4: Playlists & teachers
A5: Main playlist | D5: DSA - Abdul Bari · Abdul Bari [163 videos]
A6: Revision / PYQ playlist | D6: Algorithms - Revision, GATE PYQs Complete Analysis | GO Classes | Sachin Mittal · Sachin Mittal (GO Classes) [18 videos]
A7: More | D7: Computer Sc - Design & Analysis of Algorithms (NPTEL) · Prof. Abhiram Ranade, IIT Bombay [34 videos]
A8: Topic-wise PYQs | D8: GATE Overflow GO-PDFs (2025) → open 'Algorithms'
A9: Textbook | D9: CLRS (3E) – chapters given per day; Kleinberg-Tardos ch 1-6 optional
A10: Free tests | D10: GO2017 Algorithms 1 | E10: Algorithm Test 2 | F10: Algorithms Previous GATE 1 | G10: Algorithms GATE2020 PG-1 | H10: Algorithms GATE2020 PG-2
A12: Day # | B12: Date | C12: Day | D12: Aptitude today (reference – track in sheet 8) | E12: MATHS lecture today (reference – track in sheet 7) | F12: Maths playlist · teacher (click) | G12: Maths video search ▶ | H12: MAIN lecture topic | I12: What's covered | J12: Main playlist · teacher (click) | K12: Main video search ▶ | L12: Also use today: PYQ / extra playlist · teacher (click) | M12: Textbook | N12: Practice (PYQs) | O12: Planned hrs (whole day) | P12: STATUS – this subject only | Q12: Notes
A13: 1 | B13: 46324 | C13: =TEXT(B13,"ddd") -> Thu | D13: Aptitude: Percentages & ratios – 8-10 easy Qs (20 min). Source: Complete Course on General Aptitude for GATE & ESE 2025 & 2026 (Unacademy) | E13: Day 15: Connectivity | F13: Graph Theory Complete Course - Discrete Mathematics | Complete Graph Theory Course | GO Classes · GO Classes for GATE CS (instructor not named in playlist) | G13: Search this lecture ▶ | H13: Asymptotic notation & complexity analysis | I13: Big-O/Omega/Theta, growth-rate ordering, time & space complexity, analysing loops and nested loops. | J13: DSA - Abdul Bari · Abdul Bari | K13: Search this lecture ▶ | L13: Algorithms - Revision, GATE PYQs Complete Analysis | GO Classes | Sachin Mittal · Sachin Mittal (GO Classes) | M13: CLRS ch 1, 2, 3 | N13: GO-PDFs → Algorithms → Asymptotic analysis PYQs – 12 Qs | O13: 3 | P13: Not Started
A14: 2 | B14: 46325 | C14: =TEXT(B14,"ddd") -> Fri | D14: Aptitude: Time & work – 8-10 easy Qs (20 min). Source: Complete Course on General Aptitude for GATE & ESE 2025 & 2026 (Unacademy) | E14: Day 16: Trees, Euler & Hamiltonian graphs | F14: Graph Theory Complete Course - Discrete Mathematics | Complete Graph Theory Course | GO Classes · GO Classes for GATE CS (instructor not named in playlist) | G14: Search this lecture ▶ | H14: Recurrence relations | I14: Substitution, recursion tree, Master theorem (all 3 cases + gaps), recurrences of recursive algorithms. | J14: DSA - Abdul Bari · Abdul Bari | K14: Search this lecture ▶ | L14: Algorithms - Revision, GATE PYQs Complete Analysis | GO Classes | Sachin Mittal · Sachin Mittal (GO Classes) | M14: CLRS ch 4 | N14: GO-PDFs → Algorithms → Recurrence PYQs – 12 Qs | O14: 3 | P14: Not Started
A15: 3 | B15: 46326 | C15: =TEXT(B15,"ddd") -> Sat | D15: Aptitude: Speed, time & distance – 8-10 easy Qs (20 min). Source: Complete Course on General Aptitude for GATE & ESE 2025 & 2026 (Unacademy) | E15: Day 17: Planar graphs & matching | F15: Graph Theory Complete Course - Discrete Mathematics | Complete Graph Theory Course | GO Classes · GO Classes for GATE CS (instructor not named in playlist) | G15: Search this lecture ▶ | H15: Searching & basic sorting | I15: Linear/binary search, bubble, selection, insertion sort; stability, in-place, best/worst cases, inversions. | J15: DSA - Abdul Bari · Abdul Bari | K15: Search this lecture ▶ | L15: Algorithms - Revision, GATE PYQs Complete Analysis | GO Classes | Sachin Mittal · Sachin Mittal (GO Classes) | M15: CLRS ch 2 | N15: GO-PDFs → Algorithms → Sorting PYQs (basic) – 10 Qs | O15: 3 | P15: Not Started
A16: 4 | B16: 46328 | C16: =TEXT(B16,"ddd") -> Mon | D16: Aptitude: Profit/loss & averages – 8-10 easy Qs (20 min). Source: Complete Course on General Aptitude for GATE & ESE 2025 & 2026 (Unacademy) | E16: Day 18: Graph colouring | F16: Graph Theory Complete Course - Discrete Mathematics | Complete Graph Theory Course | GO Classes · GO Classes for GATE CS (instructor not named in playlist) | G16: Search this lecture ▶ | H16: Merge, quick, heap sort & lower bounds | I16: Merge sort, quick sort (partition, worst case, randomized), heap sort, counting/radix/bucket sort, Omega(n log n) bound. | J16: DSA - Abdul Bari · Abdul Bari | K16: Search this lecture ▶ | L16: Algorithms - Revision, GATE PYQs Complete Analysis | GO Classes | Sachin Mittal · Sachin Mittal (GO Classes) | M16: CLRS ch 6, 7, 8 | N16: GO-PDFs → Algorithms → Sorting PYQs (advanced) – 15 Qs | O16: 3 | P16: Not Started
A17: 5 | B17: 46329 | C17: =TEXT(B17,"ddd") -> Tue | D17: Aptitude: Number series & sequences – 8-10 easy Qs (20 min). Source: Complete Course on General Aptitude for GATE & ESE 2025 & 2026 (Unacademy) | E17: Day 19: Counting I: rules, permutations & combinations | F17: Combinatorics Complete Course | Discrete Mathematics | Basic Counting Principles, Permutation & Combination | Generating Function, Recurrence Relation · GO Classes for GATE CS (instructor not named in playlist) | G17: Search this lecture ▶ | H17: Hashing | I17: Hash functions, chaining, open addressing (linear, quadratic, double), load factor, expected probes, insertion order questions. | J17: DSA - Abdul Bari · Abdul Bari | K17: Search this lecture ▶ | L17: Algorithms - Revision, GATE PYQs Complete Analysis | GO Classes | Sachin Mittal · Sachin Mittal (GO Classes) | M17: CLRS ch 11.1-11.4 | N17: GO-PDFs → Algorithms → Hashing PYQs – 12 Qs | O17: 3 | P17: Not Started
A18: 6 | B18: 46330 | C18: =TEXT(B18,"ddd") -> Wed | D18: Aptitude: Basic counting & probability (aptitude level) – 8-10 easy Qs (20 min). Source: Complete Course on General Aptitude for GATE & ESE 2025 & 2026 (Unacademy) | E18: Day 20: Counting II: pigeonhole, inclusion-exclusion, stars & bars | F18: Combinatorics Complete Course | Discrete Mathematics | Basic Counting Principles, Permutation & Combination | Generating Function, Recurrence Relation · GO Classes for GATE CS (instructor not named in playlist) | G18: Search this lecture ▶ | H18: Divide & conquer applications | I18: D&C paradigm, min-max finding, Strassen matrix multiplication, closest pair, comparison of D&C recurrences. | J18: DSA - Abdul Bari · Abdul Bari | K18: Search this lecture ▶ | L18: Algorithms - Revision, GATE PYQs Complete Analysis | GO Classes | Sachin Mittal · Sachin Mittal (GO Classes) | M18: CLRS ch 4.2, 9 | N18: GO-PDFs → Algorithms → D&C PYQs – 10 Qs | O18: 3 | P18: Not Started
A19: 7 | B19: 46331 | C19: =TEXT(B19,"ddd") -> Thu | D19: Aptitude: Data interpretation (tables, bar charts) – 8-10 easy Qs (20 min). Source: Complete Course on General Aptitude for GATE & ESE 2025 & 2026 (Unacademy) | E19: Day 21: Recurrence relations | F19: Recurrence Relations in Discrete Mathematics | Complete Playlist | Applications of Recurrence Relations | GO Classes · GO Classes for GATE CS (instructor not named in playlist) | G19: Search this lecture ▶ | H19: Greedy algorithms | I19: Greedy choice property, fractional knapsack, activity selection, job sequencing with deadlines, Huffman coding. | J19: DSA - Abdul Bari · Abdul Bari | K19: Search this lecture ▶ | L19: Algorithms - Revision, GATE PYQs Complete Analysis | GO Classes | Sachin Mittal · Sachin Mittal (GO Classes) | M19: CLRS ch 16.1-16.3 | N19: GO-PDFs → Algorithms → Greedy PYQs – 12 Qs | O19: 3 | P19: Not Started
A20: 8 | B20: 46332 | C20: =TEXT(B20,"ddd") -> Fri | D20: Aptitude: Verbal: tenses & subject-verb agreement – 8-10 easy Qs (20 min). Source: GATE Overflow – verbal aptitude lessons | E20: Day 22: Generating functions | F20: Combinatorics Complete Course | Discrete Mathematics | Basic Counting Principles, Permutation & Combination | Generating Function, Recurrence Relation · GO Classes for GATE CS (instructor not named in playlist) | G20: Search this lecture ▶ | H20: Graph traversals | I20: BFS, DFS, edge classification, topological sort, strongly connected components, applications. | J20: DSA - Abdul Bari · Abdul Bari | K20: Search this lecture ▶ | L20: Algorithms - Revision, GATE PYQs Complete Analysis | GO Classes | Sachin Mittal · Sachin Mittal (GO Classes) | M20: CLRS ch 22.1-22.5 | N20: GO-PDFs → Algorithms → Graph traversal PYQs – 12 Qs | O20: 3 | P20: Not Started | Q20: Generating-function videos sit near the end of this long playlist.
A21: 9 | B21: 46333 | C21: =TEXT(B21,"ddd") -> Sat | D21: Aptitude: Verbal: sentence completion & prepositions – 8-10 easy Qs (20 min). Source: GATE Overflow – verbal aptitude lessons | E21: Day 23: Matrices: types & operations | F21: Linear Algebra | GATE CSE Complete Course · GO Classes for GATE CS (instructor not named in playlist) | G21: Search this lecture ▶ | H21: Minimum spanning trees & union-find | I21: Cut property, Kruskal, Prim, union-find with path compression, number of MSTs, uniqueness conditions. | J21: DSA - Abdul Bari · Abdul Bari | K21: Search this lecture ▶ | L21: Algorithms - Revision, GATE PYQs Complete Analysis | GO Classes | Sachin Mittal · Sachin Mittal (GO Classes) | M21: CLRS ch 21, 23 | N21: GO-PDFs → Algorithms → MST PYQs – 12 Qs | O21: 3 | P21: Not Started
A22: 10 | B22: 46335 | C22: =TEXT(B22,"ddd") -> Mon | D22: Aptitude: Verbal: synonyms, antonyms & idioms – 8-10 easy Qs (20 min). Source: GATE Overflow – verbal aptitude lessons | E22: Day 24: Determinants | F22: Linear Algebra | GATE CSE Complete Course · GO Classes for GATE CS (instructor not named in playlist) | G22: Search this lecture ▶ | H22: Shortest paths | I22: Dijkstra, Bellman-Ford, Floyd-Warshall, negative edges/cycles, complexity with different data structures. | J22: DSA - Abdul Bari · Abdul Bari | K22: Search this lecture ▶ | L22: Algorithms - Revision, GATE PYQs Complete Analysis | GO Classes | Sachin Mittal · Sachin Mittal (GO Classes) | M22: CLRS ch 24, 25.2 | N22: GO-PDFs → Algorithms → Shortest-path PYQs – 12 Qs | O22: 3 | P22: Not Started
A23: 11 | B23: 46336 | C23: =TEXT(B23,"ddd") -> Tue | D23: Aptitude: Reading comprehension (1 passage) – 8-10 easy Qs (20 min). Source: GATE Overflow – verbal aptitude lessons | E23: Day 25: Rank & inverse | F23: Linear Algebra | GATE CSE Complete Course · GO Classes for GATE CS (instructor not named in playlist) | G23: Search this lecture ▶ | H23: Dynamic programming I | I23: DP idea (overlapping subproblems, optimal substructure), LCS, LIS, matrix-chain multiplication. | J23: DSA - Abdul Bari · Abdul Bari | K23: Search this lecture ▶ | L23: Algorithms - Revision, GATE PYQs Complete Analysis | GO Classes | Sachin Mittal · Sachin Mittal (GO Classes) | M23: CLRS ch 15 | N23: GO-PDFs → Algorithms → DP PYQs (part 1) – 10 Qs | O23: 3 | P23: Not Started
A24: 12 | B24: 46337 | C24: =TEXT(B24,"ddd") -> Wed | D24: Aptitude: Para-jumbles & sentence ordering – 8-10 easy Qs (20 min). Source: GATE Overflow – verbal aptitude lessons | E24: Day 26: Systems of linear equations | F24: Linear Algebra | GATE CSE Complete Course · GO Classes for GATE CS (instructor not named in playlist) | G24: Search this lecture ▶ | H24: Dynamic programming II | I24: 0/1 knapsack, coin change, edit distance, subset sum, rod cutting, DP vs greedy. | J24: DSA - Abdul Bari · Abdul Bari | K24: Search this lecture ▶ | L24: Algorithms - Revision, GATE PYQs Complete Analysis | GO Classes | Sachin Mittal · Sachin Mittal (GO Classes) | M24: CLRS ch 15 | N24: GO-PDFs → Algorithms → DP PYQs (part 2) – 12 Qs | O24: 3 | P24: Not Started
A25: 13 | B25: 46338 | C25: =TEXT(B25,"ddd") -> Thu | D25: Aptitude: Logical reasoning: arrangements & puzzles – 8-10 easy Qs (20 min). Source: Complete Course on General Aptitude for GATE & ESE 2025 & 2026 (Unacademy) | E25: Day 27: Eigenvalues & eigenvectors | F25: Linear Algebra | GATE CSE Complete Course · GO Classes for GATE CS (instructor not named in playlist) | G25: Search this lecture ▶ | H25: Uni-only: backtracking, branch & bound, NP-completeness | I25: Not in GATE 2027 syllabus but likely in your IPU DAA paper: N-Queens, graph colouring, branch & bound, P/NP/NP-complete, reductions (SAT, vertex cover). | J25: DSA - Abdul Bari · Abdul Bari | K25: Search this lecture ▶ | L25: Algorithms - Revision, GATE PYQs Complete Analysis | GO Classes | Sachin Mittal · Sachin Mittal (GO Classes) | M25: CLRS ch 34 (overview) | N25: GO-PDFs → Algorithms → Collect last 3 yrs IPU DAA papers; solve the NP/backtracking questions | O25: 3 | P25: Not Started
N26: Total planned hours | O26: =SUM(O13:O25) -> 39

Sheet 4 Compiler Design
A1: Compiler Design – day-by-day plan
A2: GATE + Uni (CIC-303 CD, 17 Dec) | The STATUS column here tracks only THIS subject. Maths is tracked in sheet 7, Aptitude in sheet 8.
A4: Playlists & teachers
A5: Main playlist | D5: Compiler Design - GATE Computer Science Classes · Prof. Ravindrababu Ravula [49 videos]
A6: Revision / PYQ playlist | D6: Compiler Design (GO Classes – GATE PYQs & revision) · GO Classes for GATE CS (instructor not named in playlist) [22 videos]
A7: More | D7: Compiler Design : Intermediate Code & Code Optimization | Local Optimization | Dataflow Analysis | Liveness Analysis · GO Classes for GATE CS (instructor not named in playlist) [10 videos]
A8: More | D8: CS3300 Compiler Design (IIT Madras) · Dr. Rupesh Nasre, IIT Madras [48 videos]
A9: Topic-wise PYQs | D9: GATE Overflow GO-PDFs (2025) → open 'Compiler Design'
A10: Textbook | D10: Dragon Book (Aho, Lam, Sethi, Ullman, 2E) – chapters given per day
A11: Free tests | D11: GO2019 Compiler 1 – Parsing | E11: Compiler Design | F11: Compilers GATE2020 PG-1 | G11: Compilers GATE2020 PG-2 | H11: Compilers GATE2020 PG-3
A13: Day # | B13: Date | C13: Day | D13: Aptitude today (reference – track in sheet 8) | E13: MATHS lecture today (reference – track in sheet 7) | F13: Maths playlist · teacher (click) | G13: Maths video search ▶ | H13: MAIN lecture topic | I13: What's covered | J13: Main playlist · teacher (click) | K13: Main video search ▶ | L13: Also use today: PYQ / extra playlist · teacher (click) | M13: Textbook | N13: Practice (PYQs) | O13: Planned hrs (whole day) | P13: STATUS – this subject only | Q13: Notes
A14: 1 | B14: 46339 | C14: =TEXT(B14,"ddd") -> Fri | D14: Aptitude: Spatial reasoning: paper folding, cubes, patterns – 8-10 easy Qs (20 min). Source: Complete Course on General Aptitude for GATE & ESE 2025 & 2026 (Unacademy) | E14: Day 28: Eigen properties: Cayley-Hamilton & diagonalisation | F14: Linear Algebra | GATE CSE Complete Course · GO Classes for GATE CS (instructor not named in playlist) | G14: Search this lecture ▶ | H14: Compiler phases & lexical analysis | I14: Phases of a compiler, tokens/lexemes/patterns, regex to DFA recap, lexical errors, symbol table, lex tool. | J14: Compiler Design - GATE Computer Science Classes · Prof. Ravindrababu Ravula | K14: Search this lecture ▶ | L14: Compiler Design (GO Classes – GATE PYQs & revision) · GO Classes for GATE CS (instructor not named in playlist) | M14: Dragon ch 1, 3 | N14: GO-PDFs → Compiler Design → Lexical analysis PYQs – 10 Qs | O14: 3 | P14: Not Started
A15: 2 | B15: 46340 | C15: =TEXT(B15,"ddd") -> Sat | D15: Aptitude: Percentages & ratios – 8-10 easy Qs (20 min). Source: Complete Course on General Aptitude for GATE & ESE 2025 & 2026 (Unacademy) | E15: Day 29: LU decomposition + LA problem-solving | F15: Linear Algebra | GATE CSE Complete Course · GO Classes for GATE CS (instructor not named in playlist) | G15: Search this lecture ▶ | H15: Parsing I: top-down & LL(1) | I15: CFG recap, ambiguity, left recursion elimination, left factoring, FIRST & FOLLOW, LL(1) table construction. | J15: Compiler Design - GATE Computer Science Classes · Prof. Ravindrababu Ravula | K15: Search this lecture ▶ | L15: Compiler Design (GO Classes – GATE PYQs & revision) · GO Classes for GATE CS (instructor not named in playlist) | M15: Dragon ch 4.1-4.4 | N15: GO-PDFs → Compiler Design → FIRST/FOLLOW & LL(1) PYQs – 15 Qs | O15: 3 | P15: Not Started | Q15: Finish with 8-10 LA PYQs.
A16: 3 | B16: 46342 | C16: =TEXT(B16,"ddd") -> Mon | D16: Aptitude: Time & work – 8-10 easy Qs (20 min). Source: Complete Course on General Aptitude for GATE & ESE 2025 & 2026 (Unacademy) | E16: Day 30: Probability basics | F16: Probability and Statistics for Engineering | GATE | gradeup · Channel: Algorithm Unlocked (instructor not named in playlist) | G16: Search this lecture ▶ | H16: Parsing II: bottom-up, LR(0) & SLR(1) | I16: Shift-reduce parsing, handles, LR items, closure/goto, LR(0) and SLR(1) tables and conflicts. | J16: Compiler Design - GATE Computer Science Classes · Prof. Ravindrababu Ravula | K16: Search this lecture ▶ | L16: Compiler Design (GO Classes – GATE PYQs & revision) · GO Classes for GATE CS (instructor not named in playlist) | M16: Dragon ch 4.5-4.6 | N16: GO-PDFs → Compiler Design → LR(0)/SLR PYQs – 12 Qs | O16: 3 | P16: Not Started
A17: 4 | B17: 46343 | C17: =TEXT(B17,"ddd") -> Tue | D17: Aptitude: Speed, time & distance – 8-10 easy Qs (20 min). Source: Complete Course on General Aptitude for GATE & ESE 2025 & 2026 (Unacademy) | E17: Day 31: Conditional probability & independence | F17: Probability and Statistics for Engineering | GATE | gradeup · Channel: Algorithm Unlocked (instructor not named in playlist) | G17: Search this lecture ▶ | H17: Parsing III: CLR(1), LALR(1), operator precedence | I17: CLR(1) items, LALR(1) merging, parser power hierarchy, SR/RR conflicts, operator-precedence parsing (uni). | J17: Compiler Design - GATE Computer Science Classes · Prof. Ravindrababu Ravula | K17: Search this lecture ▶ | L17: Compiler Design (GO Classes – GATE PYQs & revision) · GO Classes for GATE CS (instructor not named in playlist) | M17: Dragon ch 4.7-4.8 | N17: GO-PDFs → Compiler Design → CLR/LALR PYQs – 12 Qs | O17: 3 | P17: Not Started
A18: 5 | B18: 46344 | C18: =TEXT(B18,"ddd") -> Wed | D18: Aptitude: Profit/loss & averages – 8-10 easy Qs (20 min). Source: Complete Course on General Aptitude for GATE & ESE 2025 & 2026 (Unacademy) | E18: Day 32: Bayes' theorem & total probability | F18: Probability and Statistics for Engineering | GATE | gradeup · Channel: Algorithm Unlocked (instructor not named in playlist) | G18: Search this lecture ▶ | H18: Syntax-directed translation | I18: SDD & SDT, synthesized vs inherited attributes, S-attributed & L-attributed, dependency graph, evaluation order. | J18: Compiler Design - GATE Computer Science Classes · Prof. Ravindrababu Ravula | K18: Search this lecture ▶ | L18: Compiler Design (GO Classes – GATE PYQs & revision) · GO Classes for GATE CS (instructor not named in playlist) | M18: Dragon ch 5 | N18: GO-PDFs → Compiler Design → SDT PYQs – 10 Qs | O18: 3 | P18: Not Started
A19: 6 | B19: 46345 | C19: =TEXT(B19,"ddd") -> Thu | D19: Aptitude: Number series & sequences – 8-10 easy Qs (20 min). Source: Complete Course on General Aptitude for GATE & ESE 2025 & 2026 (Unacademy) | E19: Day 33: Random variables: PMF, PDF, CDF | F19: Probability and Statistics for Engineering | GATE | gradeup · Channel: Algorithm Unlocked (instructor not named in playlist) | G19: Search this lecture ▶ | H19: Intermediate code & runtime environments | I19: Three-address code, quadruples/triples, DAG, backpatching; activation records, stack/heap allocation, parameter passing, scope. | J19: Compiler Design - GATE Computer Science Classes · Prof. Ravindrababu Ravula | K19: Search this lecture ▶ | L19: Compiler Design : Intermediate Code & Code Optimization | Local Optimization | Dataflow Analysis | Liveness Analysis · GO Classes for GATE CS (instructor not named in playlist) + Compiler Design (GO Classes – GATE PYQs & revision) · GO Classes for GATE CS (instructor not named in playlist) | M19: Dragon ch 6, 7 | N19: GO-PDFs → Compiler Design → ICG & runtime PYQs – 12 Qs | O19: 3 | P19: Not Started
A20: 7 | B20: 46346 | C20: =TEXT(B20,"ddd") -> Fri | D20: Aptitude: Basic counting & probability (aptitude level) – 8-10 easy Qs (20 min). Source: Complete Course on General Aptitude for GATE & ESE 2025 & 2026 (Unacademy) | E20: Day 34: Expectation, variance & standard deviation | F20: Probability and Statistics for Engineering | GATE | gradeup · Channel: Algorithm Unlocked (instructor not named in playlist) | G20: Search this lecture ▶ | H20: Code optimisation & data-flow analysis | I20: Basic blocks & flow graph, local optimisation, constant propagation, liveness analysis, common-subexpression elimination, GEN/KILL. | J20: Compiler Design - GATE Computer Science Classes · Prof. Ravindrababu Ravula | K20: Search this lecture ▶ | L20: Compiler Design : Intermediate Code & Code Optimization | Local Optimization | Dataflow Analysis | Liveness Analysis · GO Classes for GATE CS (instructor not named in playlist) + Compiler Design (GO Classes – GATE PYQs & revision) · GO Classes for GATE CS (instructor not named in playlist) | M20: Dragon ch 8.4-8.5, 9.1-9.2 | N20: GO-PDFs → Compiler Design → Optimisation PYQs – 12 Qs + full CD recap | O20: 3 | P20: Not Started
N21: Total planned hours | O21: =SUM(O14:O20) -> 21

Sheet 5 Operating Systems
A1: Operating Systems – day-by-day plan
A2: GATE + Uni (CIC-305 OS, 19 Dec) | The STATUS column here tracks only THIS subject. Maths is tracked in sheet 7, Aptitude in sheet 8.
A4: Playlists & teachers
A5: Main playlist | D5: Operating System | GATE 2022 | Vishavdeep Sir · Vishavdeep (Vishvadeep) Sir [62 videos]
A6: Revision / PYQ playlist | D6: Operating Systems GATE PYQs, Revision Playlist · GO Classes for GATE CS (instructor not named in playlist) [11 videos]
A7: More | D7: Introduction to Operating Systems | IIT Madras (NPTEL) · NPTEL-NOC IITM (instructor not named in playlist) [39 videos]
A8: Topic-wise PYQs | D8: GATE Overflow GO-PDFs (2025) → open 'Operating System'
A9: Textbook | D9: Silberschatz, Galvin, Gagne – Operating System Concepts (9E)
A10: Free tests | D10: GO2017 OS 1 | E10: GO2017 OS 2 | F10: GO2017 OS 3 | G10: OS GATE2020 Previous GATE 2
A12: Day # | B12: Date | C12: Day | D12: Aptitude today (reference – track in sheet 8) | E12: MATHS lecture today (reference – track in sheet 7) | F12: Maths playlist · teacher (click) | G12: Maths video search ▶ | H12: MAIN lecture topic | I12: What's covered | J12: Main playlist · teacher (click) | K12: Main video search ▶ | L12: Also use today: PYQ / extra playlist · teacher (click) | M12: Textbook | N12: Practice (PYQs) | O12: Planned hrs (whole day) | P12: STATUS – this subject only | Q12: Notes
A13: 1 | B13: 46347 | C13: =TEXT(B13,"ddd") -> Sat | D13: Aptitude: Data interpretation (tables, bar charts) – 8-10 easy Qs (20 min). Source: Complete Course on General Aptitude for GATE & ESE 2025 & 2026 (Unacademy) | E13: Day 35: Binomial distribution | F13: Probability and Statistics for Engineering | GATE | gradeup · Channel: Algorithm Unlocked (instructor not named in playlist) | G13: Search this lecture ▶ | H13: OS basics, system calls & processes | I13: OS functions & types, kernel/user mode, system calls, process concept, PCB, states, context switch, fork() output questions. | J13: Operating System | GATE 2022 | Vishavdeep Sir · Vishavdeep (Vishvadeep) Sir | K13: Search this lecture ▶ | L13: Operating Systems GATE PYQs, Revision Playlist · GO Classes for GATE CS (instructor not named in playlist) | M13: Silberschatz ch 2.1-2.5, 3 | N13: GO-PDFs → Operating System → fork()/process PYQs – 10 Qs | O13: 3 | P13: Not Started
A14: 2 | B14: 46349 | C14: =TEXT(B14,"ddd") -> Mon | D14: Aptitude: Verbal: tenses & subject-verb agreement – 8-10 easy Qs (20 min). Source: GATE Overflow – verbal aptitude lessons | E14: Day 36: Poisson distribution | F14: Probability and Statistics for Engineering | GATE | gradeup · Channel: Algorithm Unlocked (instructor not named in playlist) | G14: Search this lecture ▶ | H14: Threads & inter-process communication | I14: User vs kernel threads, multithreading models, pthreads, IPC: shared memory, message passing, pipes. | J14: Operating System | GATE 2022 | Vishavdeep Sir · Vishavdeep (Vishvadeep) Sir | K14: Search this lecture ▶ | L14: Operating Systems GATE PYQs, Revision Playlist · GO Classes for GATE CS (instructor not named in playlist) | M14: Silberschatz ch 4.1-4.3, 4.6; ch 3 (IPC) | N14: GO-PDFs → Operating System → Threads/IPC PYQs – 10 Qs | O14: 3 | P14: Not Started
